Workbook

Sheet Index
B2: PIKETTY-ZUCMAN WEALTH-INCOME DATA SET
B3: This database supports our paper "Capital is Back: Wealth-Income Ratios in Rich Countries, 1700-2010"
B6: Germany, 1870-2010
B7: Last update: June 4, 2013
B9: Summary Macro Variables
B10: =TableDE1!A3 -> Table DE.1: National income and private wealth in Germany, 1870-2011 (annual series)
B11: =TableDE2!A3 -> Table DE.2: National income and private wealth in Germany, 1870-2010 (decennial averages)
B12: =TableDE3!A3 -> Table DE.3: Economic growth, population growth and price deflators in Germany (changing boundaries), 1870-2010
B13: =TableDE3b!A3 -> Table DE.3b: Economic and population growth in Germany, 1870-2011: Corrections for frontier changes
B14: =TableDE3c!A3 -> Table DE.3c: Economic growth, population growth and price deflators in Germany (fixed boundaries), 1870-2010
B15: =TableDE3d!A3 -> Table DE.3d: Summary macro variables, 1870-2011 (annual series)
B16: =TableDE3e!A3 -> Table DE.3e: Summary macro variables, 1870-2010 (decennial averages)
B17: Wealth Accumulation
B18: =TableDE4a!A3 -> Table DE.4a: Sources of private wealth accumulation in Germany, 1870-2010 - Additive decomposition
B19: =Table_DE_4b__Sources_of_private_wealth_accumulation_in_Germany__1870_2010___Multiplicative_decomposition -> Table DE.4b: Sources of private wealth accumulation in Germany, 1870-2010 - Multiplicative decomposition
B20: =TableDE4c!A3 -> Table DE.4c: Sources of market value national wealth accumulation in Germany, 1870-2010
B21: =TableDE4e!A3 -> Table DE.4e: Sources of government wealth accumulation in Germany, 1870-2010
B22: =TableDE4f!A3 -> Table DE.4f: Sources of foreign wealth accumulation in Germany, 1870-2010
B23: =TableDE4g!A3 -> Table DE.4g: Sources of book value national wealth accumulation in Germany, 1970-2010
B24: =TableDE5a!A3 -> Table DE.5a: Accumulation equation for private wealth in Germany, 1870-2010 (annual series)
B25: =TableDE5b!A3 -> Table DE.5b: Accumulation equation for national wealth in Germany, 1870-2010 (annual series)
B26: =TableDE5c!A3 -> Table DE.5c: Accumulation equation for government wealth in Germany, 1870-2010 (annual series)
B27: Structure of National Wealth
B28: =TableDE6a!A3 -> Table DE.6a: Structure of national wealth in Germany, 1870-2011: private wealth vs government wealth
B29: =TableDE6b!A3 -> Table DE.6b: Structure of national wealth in Germany, 1870-2011: corporate wealth and net foreign asset position
B30: =TableDE6c!A3 -> Table DE.6c: Composition of private wealth in Germany, 1950-2011, % of national income
B31: =TableDE6d!A3 -> Table DE.6d: Composition of private wealth in Germany, 1950-2011, % of private wealth
B32: =TableDE6e!A3 -> Table DE.6e: The structure of national wealth in Germany, 1870-2010 (decenial averages)
B33: =TableDE6f!A3 -> Table DE.6f: The changing nature of national wealth in Germany, 1870-2010
B34: =TableDE6g!A3 -> Table DE.6g: Assets and liabilities in Eastern Germany as of 1991 and 1998
B35: Structure of National Income
B36: =TableDE8!A3 -> Table DE.8: Structure of national income in Germany, 1950-2011: national income vs gross domestic product
B37: =TableDE9!A3 -> Table DE.9: Structure of national income in Germany, 1950-2011: decomposition by production sectors
B38: =TableDE10!A3 -> Table DE.10: Structure of national income in Germany, 1980-2011: profits & wages in the corporate sector
B39: =TableDE11a!A3 -> Table DE.11a: Structure of national income in Germany, 1950-2010: capital & labor shares in national income
B40: =TableDE11b!A3 -> Table DE.11b: Structure of national income in Germany, 1950-2011: capital & labor shares in factor-price national income
B41: =TableDE12!A4 -> Table DE.12: Structure of national income in Germany, 1950-2010: disposable income & savings
B42: =TableDE12b!A3 -> Table DE12b: Structure of national income in Germany, 1870-2010: savings, investment and external balance
B43: =TableDE12c!A3 -> Table DE12c: Structure of national income in Germany, 1870-2010: private vs government saving, investment, and depreciation
B44: =TableDE13!A3 -> Table DE.13: Structure of national income in Germany, 1950-2010: taxes & transfers
...

Sheet TableDE1
B1: Back to index
A3: Table DE.1: National income and private wealth in Germany, 1870-2011 (annual series)
B5: [1] | C5: [2] | D5: [3] | E5: [4] | F5: [5] | G5: [6] | H5: [7] | I5: [8] | J5: [9] | K5: [10] | L5: [11] | M5: [12] | N5: [13] | O5: [14] | P5: [15] | Q5: [16] | R5: [17] | S5: [18] | T5: [19] | U5: [20]
B6: Boundaries: 1870-1944: German Empire (including Alsace-Lorraine from 1871 on, excluding territories lost in the wake of World War 1 from 1919-1923 on, including Saarland from 1935 on, and including annexed territories in 1938-1944); 1945-1949: territory occupied by the Allied powers and USSR; 1950-1990: West Germany (including Saarland & West Berlin); 1991-onwards: reunified Germany.
B7: (1850-1949: current bn marks; 1950-onwards: current bn euros) | D7: (2010 billions euros) | F7: (1850-1949: current bn marks; 1950-onwards: current bn euros) | J7: (2010 euros) | N7: Ratio (private wealth)/ (national income) βt = Wt/Yt | O7: memo: Ratio (dispos. income)/ (national income) | P7: memo: Per adult dispos. income (2010 €) | Q7: memo: Ratio (private wealth)/ (dispos. income) | R7: Population (thousands, mid-year) | S7: Adult population (20-yr+) | T7: Employed population | U7: Land area (1000 km2)
D8: National income Yt | E8: Private wealth Wt | F8: Per capita national income | G8: Per capita private wealth | H8: Per adult national income yt | I8: Per adult private wealth wt | J8: Per capita national income | K8: Per capita private wealth | L8: Per adult national income yt | M8: Per adult private wealth wt
B9: National income Yt | C9: Private wealth Wt | R9: Nt | S9: Nt20+ | T9: Lt
A10: 1870 | B10: =DataDE1c!B33 -> 12.876 | C10: =N10*B10 -> 90.610518 | D10: =B10*(TableDE15a!C$149/TableDE15a!C9)/1.95583 -> 94.828634 | E10: =D10*N10 -> 667.32461 | F10: =1000000*B10/R10 -> 328.20983 | G10: =1000000*C10/R10 -> 2309.6663 | H10: =1000000*B10/S10 -> 580.7513 | I10: =1000000*C10/S10 -> 4086.8419 | J10: =1000000*D10/R10 -> 2417.1863 | K10: =1000000*E10/R10 -> 17010.135 | L10: =1000000*D10/S10 -> 4277.0932 | M10: =1000000*E10/S10 -> 30098.605 | N10: =TableDE5a!F10 -> 7.0371635 | O10: =DataDE1c!AW33/DataDE1c!B33 -> 0.95588692 | P10: =O10*L10 -> 4088.4175 | Q10: =M10/P10 -> 7.3619205 | R10: =DataDE1c!BK33 -> 39231 | S10: =R10*(1-DataDE1c!BN33) -> 22171.281 | T10: =DataDE1c!BO33 -> 17045.5 | U10: 533.1
A11: 1871 | B11: =DataDE1c!B34 -> 14.013 | C11: =N11*B11 -> 96.64773 | D11: =B11*(TableDE15a!C$149/TableDE15a!C10)/1.95583 -> 98.720872 | E11: =D11*N11 -> 680.87834 | F11: =1000000*B11/R11 -> 341.82217 | G11: =1000000*C11/R11 -> 2357.5492 | H11: =1000000*B11/S11 -> 604.83767 | I11: =1000000*C11/S11 -> 4171.5684 | J11: =1000000*D11/R11 -> 2408.1198 | K11: =1000000*E11/R11 -> 16608.814 | L11: =1000000*D11/S11 -> 4261.0506 | M11: =1000000*E11/S11 -> 29388.487 | N11: =TableDE5a!F11 -> 6.8970049 | O11: =DataDE1c!AW34/DataDE1c!B34 -> 0.95703989 | P11: =O11*L11 -> 4077.9954 | Q11: =M11/P11 -> 7.2066013 | R11: =DataDE1c!BK34 -> 40995 | S11: =R11*(1-DataDE1c!BN34) -> 23168.2 | T11: =DataDE1c!BO34 -> 17337 | U11: 540.6
A12: 1872 | B12: =DataDE1c!B35 -> 16.627 | C12: =N12*B12 -> 104.67993 | D12: =B12*(TableDE15a!C$149/TableDE15a!C11)/1.95583 -> 109.14672 | E12: =D12*N12 -> 687.16372 | F12: =1000000*B12/R12 -> 403.71494 | G12: =1000000*C12/R12 -> 2541.7004 | H12: =1000000*B12/S12 -> 712.21541 | I12: =1000000*C12/S12 -> 4483.9514 | J12: =1000000*D12/R12 -> 2650.1571 | K12: =1000000*E12/R12 -> 16684.806 | L12: =1000000*D12/S12 -> 4675.2858 | M12: =1000000*E12/S12 -> 29434.57 | N12: =TableDE5a!F12 -> 6.2957798 | O12: =DataDE1c!AW35/DataDE1c!B35 -> 0.96313225 | P12: =O12*L12 -> 4502.9186 | Q12: =M12/P12 -> 6.536776 | R12: =DataDE1c!BK35 -> 41185 | S12: =R12*(1-DataDE1c!BN35) -> 23345.465 | T12: =DataDE1c!BO35 -> 17663.5 | U12: 540.6
A13: 1873 | B13: =DataDE1c!B36 -> 17.95 | C13: =N13*B13 -> 113.64915 | D13: =B13*(TableDE15a!C$149/TableDE15a!C12)/1.95583 -> 111.759 | E13: =D13*N13 -> 707.59421 | F13: =1000000*B13/R13 -> 432.19686 | G13: =1000000*C13/R13 -> 2736.4238 | H13: =1000000*B13/S13 -> 760.1862 | I13: =1000000*C13/S13 -> 4813.065 | J13: =1000000*D13/R13 -> 2690.9131 | K13: =1000000*E13/R13 -> 17037.326 | L13: =1000000*D13/S13 -> 4733.0168 | M13: =1000000*E13/S13 -> 29966.76 | N13: =TableDE5a!F13 -> 6.3314291 | O13: =DataDE1c!AW36/DataDE1c!B36 -> 0.95749304 | P13: =O13*L13 -> 4531.8306 | Q13: =M13/P13 -> 6.6125067 | R13: =DataDE1c!BK36 -> 41532 | S13: =R13*(1-DataDE1c!BN36) -> 23612.636 | T13: =DataDE1c!BO36 -> 17990 | U13: 540.6
A14: 1874 | B14: =DataDE1c!B37 -> 19.544 | C14: =N14*B14 -> 117.51057 | D14: =B14*(TableDE15a!C$149/TableDE15a!C13)/1.95583 -> 121.01996 | E14: =D14*N14 -> 727.64661 | F14: =1000000*B14/R14 -> 465.52176 | G14: =1000000*C14/R14 -> 2799.0037 | H14: =1000000*B14/S14 -> 816.3644 | I14: =1000000*C14/S14 -> 4908.4859 | J14: =1000000*D14/R14 -> 2882.5945 | K14: =1000000*E14/R14 -> 17331.935 | L14: =1000000*D14/S14 -> 5055.0753 | M14: =1000000*E14/S14 -> 30394.228 | N14: =TableDE5a!F14 -> 6.0126163 | O14: =DataDE1c!AW37/DataDE1c!B37 -> 0.96162505 | P14: =O14*L14 -> 4861.087 | Q14: =M14/P14 -> 6.2525579 | R14: =DataDE1c!BK37 -> 41983 | S14: =R14*(1-DataDE1c!BN37) -> 23940.289 | T14: =DataDE1c!BO37 -> 18316.5 | U14: 540.6
A15: 1875 | B15: =DataDE1c!B38 -> 18.242 | C15: =N15*B15 -> 116.48561 | D15: =B15*(TableDE15a!C$149/TableDE15a!C14)/1.95583 -> 119.47203 | E15: =D15*N15 -> 762.89729 | F15: =1000000*B15/R15 -> 429.12256 | G15: =1000000*C15/R15 -> 2740.1931 | H15: =1000000*B15/S15 -> 750.30004 | I15: =1000000*C15/S15 -> 4791.095 | J15: =1000000*D15/R15 -> 2810.4454 | K15: =1000000*E15/R15 -> 17946.302 | L15: =1000000*D15/S15 -> 4913.9278 | M15: =1000000*E15/S15 -> 31378.241 | N15: =TableDE5a!F15 -> 6.3855721 | O15: =DataDE1c!AW38/DataDE1c!B38 -> 0.95943427 | P15: =O15*L15 -> 4714.5908 | Q15: =M15/P15 -> 6.6555598 | R15: =DataDE1c!BK38 -> 42510 | S15: =R15*(1-DataDE1c!BN38) -> 24312.94 | T15: =DataDE1c!BO38 -> 18643 | U15: 540.6
A16: 1876 | B16: =DataDE1c!B39 -> 17.912 | C16: =N16*B16 -> 114.16671 | D16: =B16*(TableDE15a!C$149/TableDE15a!C15)/1.95583 -> 118.26563 | E16: =D16*N16 -> 753.79617 | F16: =1000000*B16/R16 -> 416.00669 | G16: =1000000*C16/R16 -> 2651.5249 | H16: =1000000*B16/S16 -> 725.21588 | I16: =1000000*C16/S16 -> 4622.3487 | J16: =1000000*D16/R16 -> 2746.7224 | K16: =1000000*E16/R16 -> 17506.937 | L16: =1000000*D16/S16 -> 4788.3045 | M16: =1000000*E16/S16 -> 30519.482 | N16: =TableDE5a!F16 -> 6.3737554 | O16: =DataDE1c!AW39/DataDE1c!B39 -> 0.95801697 | P16: =O16*L16 -> 4587.277 | Q16: =M16/P16 -> 6.6530715 | R16: =DataDE1c!BK39 -> 43057 | S16: =R16*(1-DataDE1c!BN39) -> 24698.852 | T16: =DataDE1c!BO39 -> 18891 | U16: 540.6
A17: 1877 | B17: =DataDE1c!B40 -> 17.414 | C17: =N17*B17 -> 111.59336 | D17: =B17*(TableDE15a!C$149/TableDE15a!C16)/1.95583 -> 117.57512 | E17: =D17*N17 -> 753.45143 | F17: =1000000*B17/R17 -> 399.3304 | G17: =1000000*C17/R17 -> 2559.0112 | H17: =1000000*B17/S17 -> 694.09119 | I17: =1000000*C17/S17 -> 4447.9136 | J17: =1000000*D17/R17 -> 2696.1825 | K17: =1000000*E17/R17 -> 17277.826 | L17: =1000000*D17/S17 -> 4686.3362 | M17: =1000000*E17/S17 -> 30031.239 | N17: =TableDE5a!F17 -> 6.4082554 | O17: =DataDE1c!AW40/DataDE1c!B40 -> 0.95716091 | P17: =O17*L17 -> 4485.5778 | Q17: =M17/P17 -> 6.695066 | R17: =DataDE1c!BK40 -> 43608 | S17: =R17*(1-DataDE1c!BN40) -> 25088.922 | T17: =DataDE1c!BO40 -> 19108 | U17: 540.6
A18: 1878 | B18: =DataDE1c!B41 -> 17.874 | C18: =N18*B18 -> 109.90173 | D18: =B18*(TableDE15a!C$149/TableDE15a!C17)/1.95583 -> 123.77154 | E18: =D18*N18 -> 761.03319 | F18: =1000000*B18/R18 -> 405.05813 | G18: =1000000*C18/R18 -> 2490.578 | H18: =1000000*B18/S18 -> 701.97632 | I18: =1000000*C18/S18 -> 4316.2367 | J18: =1000000*D18/R18 -> 2804.8937 | K18: =1000000*E18/R18 -> 17246.429 | L18: =1000000*D18/S18 -> 4860.954 | M18: =1000000*E18/S18 -> 29888.513 | N18: =TableDE5a!F18 -> 6.1486927 | O18: =DataDE1c!AW41/DataDE1c!B41 -> 0.95703256 | P18: =O18*L18 -> 4652.0913 | Q18: =M18/P18 -> 6.4247477 | R18: =DataDE1c!BK41 -> 44127 | S18: =R18*(1-DataDE1c!BN41) -> 25462.397 | T18: =DataDE1c!BO41 -> 19277 | U18: 540.6
A19: 1879 | B19: =DataDE1c!B42 -> 16.678 | C19: =N19*B19 -> 108.40044 | D19: =B19*(TableDE15a!C$149/TableDE15a!C18)/1.95583 -> 120.33228 | E19: =D19*N19 -> 782.11246 | F19: =1000000*B19/R19 -> 373.61948 | G19: =1000000*C19/R19 -> 2428.3796 | H19: =1000000*B19/S19 -> 645.59377 | I19: =1000000*C19/S19 -> 4196.1054 | J19: =1000000*D19/R19 -> 2695.676 | K19: =1000000*E19/R19 -> 17520.833 | L19: =1000000*D19/S19 -> 4657.9787 | M19: =1000000*E19/S19 -> 30275.029 | N19: =TableDE5a!F19 -> 6.4996065 | O19: =DataDE1c!AW42/DataDE1c!B42 -> 0.95041372 | P19: =O19*L19 -> 4427.0069 | Q19: =M19/P19 -> 6.8387128 | R19: =DataDE1c!BK42 -> 44639 | S19: =R19*(1-DataDE1c!BN42) -> 25833.583 | T19: =DataDE1c!BO42 -> 19554 | U19: 540.6
A20: 1880 | B20: =DataDE1c!B43 -> 16.914 | C20: =N20*B20 -> 109.26095 | D20: =B20*(TableDE15a!C$149/TableDE15a!C19)/1.95583 -> 116.83889 | E20: =D20*N20 -> 754.75507 | F20: =1000000*B20/R20 -> 375.09148 | G20: =1000000*C20/R20 -> 2423.0134 | H20: =1000000*B20/S20 -> 646.2424 | I20: =1000000*C20/S20 -> 4174.5924 | J20: =1000000*D20/R20 -> 2591.0649 | K20: =1000000*E20/R20 -> 16737.744 | L20: =1000000*D20/S20 -> 4464.127 | M20: =1000000*E20/S20 -> 28837.338 | N20: =TableDE5a!F20 -> 6.4597934 | O20: =DataDE1c!AW43/DataDE1c!B43 -> 0.94992314 | P20: =O20*L20 -> 4240.5775 | Q20: =M20/P20 -> 6.8003327 | R20: =DataDE1c!BK43 -> 45093 | S20: =R20*(1-DataDE1c!BN43) -> 26172.841 | T20: =DataDE1c!BO43 -> 19638 | U20: 540.6
A21: 1881 | B21: =DataDE1c!B44 -> 17.368 | C21: =N21*B21 -> 111.42746 | D21: =B21*(TableDE15a!C$149/TableDE15a!C20)/1.95583 -> 121.75245 | E21: =D21*N21 -> 781.12427 | F21: =1000000*B21/R21 -> 382.33611 | G21: =1000000*C21/R21 -> 2452.9446 | H21: =1000000*B21/S21 -> 658.88773 | I21: =1000000*C21/S21 -> 4227.2103 | J21: =1000000*D21/R21 -> 2680.237 | K21: =1000000*E21/R21 -> 17195.533 | L21: =1000000*D21/S21 -> 4618.9079 | M21: =1000000*E21/S21 -> 29633.417 | N21: =TableDE5a!F21 -> 6.4156762 | O21: =DataDE1c!AW44/DataDE1c!B44 -> 0.94864118 | P21: =O21*L21 -> 4381.6862 | Q21: =M21/P21 -> 6.7630167 | R21: =DataDE1c!BK44 -> 45426 | S21: =R21*(1-DataDE1c!BN44) -> 26359.574 | T21: =DataDE1c!BO44 -> 19745 | U21: 540.6
... A53: 1913 | B53: =DataDE1c!B76 -> 52.105 | C53: =N53*B53 -> 324.696 | D53: =B53*(TableDE15a!C$149/TableDE15a!C52)/1.95583 -> 295.86412 | E53: =D53*N53 -> 1843.6982 | F53: =1000000*B53/R53 -> 777.94201 | G53: =1000000*C53/R53 -> 4847.8008 | H53: =1000000*B53/S53 -> 1369.2563 | I53: =1000000*C53/S53 -> 8532.6176 | J53: =1000000*D53/R53 -> 4417.3329 | K53: =1000000*E53/R53 -> 27526.923 | L53: =1000000*D53/S53 -> 7774.9508 | M53: =1000000*E53/S53 -> 48450.157 | N53: =TableDE5a!F53 -> 6.2315709 | O53: =DataDE1c!AW76/DataDE1c!B76 -> 0.92745418 | P53: =O53*L53 -> 7210.9106 | Q53: =M53/P53 -> 6.7190067 | R53: =DataDE1c!BK76 -> 66978 | S53: =R53*(1-DataDE1c!BN76) -> 38053.504 | T53: =DataDE1c!BO76 -> 30968 | U53: 540.9
A54: 1914 | B54: =D54*1.95583*TableDE15a!C53/TableDE15a!C$149 -> 49.586625 | C54: =N54*B54 -> 295.81497 | D54: =D53*DataDE1c!C77/DataDE1c!C76 -> 273.16926 | E54: =D54*N54 -> 1629.624 | F54: =1000000*B54/R54 -> 731.47404 | G54: =1000000*C54/R54 -> 4363.6963 | H54: =1000000*B54/S54 -> 1274.6848 | I54: =1000000*C54/S54 -> 7604.2855 | J54: =1000000*D54/R54 -> 4029.6394 | K54: =1000000*E54/R54 -> 24039.298 | L54: =1000000*D54/S54 -> 7022.1498 | M54: =1000000*E54/S54 -> 41891.478 | N54: =TableDE5a!F54 -> 5.9656201 | R54: =DataDE1c!BK77 -> 67790 | S54: =R54*(1-DataDE1c!BN77) -> 38901.087 | U54: 540.9
A55: 1915 | B55: =D55*1.95583*TableDE15a!C54/TableDE15a!C$149 -> 57.042835 | C55: =N55*B55 -> 325.26924 | D55: =D54*DataDE1c!C78/DataDE1c!C77 -> 250.9447 | E55: =D55*N55 -> 1430.935 | F55: =1000000*B55/R55 -> 840.31104 | G55: =1000000*C55/R55 -> 4791.6155 | H55: =1000000*B55/S55 -> 1449.9505 | I55: =1000000*C55/S55 -> 8267.8971 | J55: =1000000*D55/R55 -> 3696.7237 | K55: =1000000*E55/R55 -> 21079.431 | L55: =1000000*D55/S55 -> 6378.6695 | M55: =1000000*E55/S55 -> 36372.403 | N55: =TableDE5a!F55 -> 5.7021927 | R55: =DataDE1c!BK78 -> 67883 | S55: =R55*(1-DataDE1c!BN78) -> 39341.229 | U55: 540.9
A56: 1916 | B56: =D56*1.95583*TableDE15a!C55/TableDE15a!C$149 -> 70.888421 | C56: =N56*B56 -> 381.55366 | D56: =D55*DataDE1c!C79/DataDE1c!C78 -> 239.31769 | E56: =D56*N56 -> 1288.1165 | F56: =1000000*B56/R56 -> 1046.8644 | G56: =1000000*C56/R56 -> 5634.6993 | H56: =1000000*B56/S56 -> 1788.7708 | I56: =1000000*C56/S56 -> 9627.9766 | J56: =1000000*D56/R56 -> 3534.1903 | K56: =1000000*E56/R56 -> 19022.617 | L56: =1000000*D56/S56 -> 6038.8495 | M56: =1000000*E56/S56 -> 32503.83 | N56: =TableDE5a!F56 -> 5.382454 | R56: =DataDE1c!BK79 -> 67715 | S56: =R56*(1-DataDE1c!BN79) -> 39629.683 | U56: 540.9
A57: 1917 | B57: =D57*1.95583*TableDE15a!C56/TableDE15a!C$149 -> 103.07864 | C57: =N57*B57 -> 521.30756 | D57: =D56*DataDE1c!C80/DataDE1c!C79 -> 233.57474 | E57: =D57*N57 -> 1181.2756 | F57: =1000000*B57/R57 -> 1530.0831 | G57: =1000000*C57/R57 -> 7738.2074 | H57: =1000000*B57/S57 -> 2589.236 | I57: =1000000*C57/S57 -> 13094.743 | J57: =1000000*D57/R57 -> 3467.1467 | K57: =1000000*E57/R57 -> 17534.669 | L57: =1000000*D57/S57 -> 5867.1723 | M57: =1000000*E57/S57 -> 29672.503 | N57: =TableDE5a!F57 -> 5.0573772 | R57: =DataDE1c!BK80 -> 67368 | S57: =R57*(1-DataDE1c!BN80) -> 39810.445 | U57: 540.9
A58: 1918 | B58: =D58*1.95583*TableDE15a!C57/TableDE15a!C$149 -> 120.25965 | C58: =N58*B58 -> 569.75132 | D58: =D57*DataDE1c!C81/DataDE1c!C80 -> 227.3249 | E58: =D58*N58 -> 1076.9919 | F58: =1000000*B58/R58 -> 1799.9977 | G58: =1000000*C58/R58 -> 8527.8071 | H58: =1000000*B58/S58 -> 3016.9026 | I58: =1000000*C58/S58 -> 14293.109 | J58: =1000000*D58/R58 -> 3402.507 | K58: =1000000*E58/R58 -> 16119.978 | L58: =1000000*D58/S58 -> 5702.803 | M58: =1000000*E58/S58 -> 27018.037 | N58: =TableDE5a!F58 -> 4.7376766 | R58: =DataDE1c!BK81 -> 66811 | S58: =R58*(1-DataDE1c!BN81) -> 39861.958 | U58: 540.9
A59: 1919 | B59: =D59*1.95583*TableDE15a!C58/TableDE15a!C$149 -> 146.67191 | C59: =N59*B59 -> 647.71188 | D59: =D58*DataDE1c!C82/DataDE1c!C81 -> 202.16877 | E59: =D59*N59 -> 892.7893 | F59: =1000000*B59/R59 -> 2331.9381 | G59: =1000000*C59/R59 -> 10297.977 | H59: =1000000*B59/S59 -> 3871.4948 | I59: =1000000*C59/S59 -> 17096.751 | J59: =1000000*D59/R59 -> 3214.2831 | K59: =1000000*E59/R59 -> 14194.466 | L59: =1000000*D59/S59 -> 5336.3683 | M59: =1000000*E59/S59 -> 23565.72 | N59: =TableDE5a!F59 -> 4.4160595 | R59: =DataDE1c!BK82 -> 62897 | S59: =R59*(1-DataDE1c!BN82) -> 37885.085
A60: 1920 | B60: =D60*1.95583*TableDE15a!C59/TableDE15a!C$149 -> 402.74688 | C60: =N60*B60 -> 1343.9315 | D60: =D59*DataDE1c!C83/DataDE1c!C82 -> 226.21707 | E60: =D60*N60 -> 754.8668 | F60: =1000000*B60/R60 -> 6592.681 | G60: =1000000*C60/R60 -> 21999.207 | H60: =1000000*B60/S60 -> 10842.637 | I60: =1000000*C60/S60 -> 36180.942 | J60: =1000000*D60/R60 -> 3703.013 | K60: =1000000*E60/R60 -> 12356.635 | L60: =1000000*D60/S60 -> 6090.1515 | M60: =1000000*E60/S60 -> 20322.309 | N60: =TableDE5a!F60 -> 3.3369136 | R60: =DataDE1c!BK83 -> 61090 | S60: =R60*(1-DataDE1c!BN83) -> 37144.736
A61: 1921 | B61: =D61*1.95583*TableDE15a!C60/TableDE15a!C$149 -> 561.34928 | C61: =N61*B61 -> 1602.5567 | D61: =D60*DataDE1c!C84/DataDE1c!C83 -> 239.8089 | E61: =D61*N61 -> 684.61362 | F61: =1000000*B61/R61 -> 9089.6461 | G61: =1000000*C61/R61 -> 25949.393 | H61: =1000000*B61/S61 -> 14810.481 | I61: =1000000*C61/S61 -> 42281.403 | J61: =1000000*D61/R61 -> 3883.1048 | K61: =1000000*E61/R61 -> 11085.604 | L61: =1000000*D61/S61 -> 6327.0503 | M61: =1000000*E61/S61 -> 18062.652 | N61: =TableDE5a!F61 -> 2.8548299 | R61: =DataDE1c!BK84 -> 61757 | S61: =R61*(1-DataDE1c!BN84) -> 37902.165
A62: 1922 | B62: =D62*1.95583*TableDE15a!C61/TableDE15a!C$149 -> 10728.3 | C62: =N62*B62 -> 25382.025 | D62: =D61*DataDE1c!C85/DataDE1c!C84 -> 254.13233 | E62: =D62*N62 -> 601.25025 | F62: =1000000*B62/R62 -> 174975.94 | G62: =1000000*C62/R62 -> 413974.61 | H62: =1000000*B62/S62 -> 282479.72 | I62: =1000000*C62/S62 -> 668317.2 | J62: =1000000*D62/R62 -> 4144.8359 | K62: =1000000*E62/R62 -> 9806.2442 | L62: =1000000*D62/S62 -> 6691.389 | M62: =1000000*E62/S62 -> 15831.12 | N62: =TableDE5a!F62 -> 2.3658944 | R62: =DataDE1c!BK85 -> 61313 | S62: =R62*(1-DataDE1c!BN85) -> 37979.009
A63: 1923 | B63: =D63*1.95583*TableDE15a!C62/TableDE15a!C$149 -> 2.6454682e+12 | C63: =N63*B63 -> 6.358065e+12 | D63: =D62*DataDE1c!C86/DataDE1c!C85 -> 221.01235 | E63: =D63*N63 -> 531.17662 | F63: =1000000*B63/R63 -> 4.2863804e+13 | G63: =1000000*C63/R63 -> 103018001680797 | H63: =1000000*B63/S63 -> 6.8568262e+13 | I63: =1000000*C63/S63 -> 164795578968036 | J63: =1000000*D63/R63 -> 3581.0031 | K63: =1000000*E63/R63 -> 8606.5107 | L63: =1000000*D63/S63 -> 5728.4501 | M63: =1000000*E63/S63 -> 13767.641 | N63: =TableDE5a!F63 -> 2.4033798 | R63: =DataDE1c!BK86 -> 61718 | S63: =R63*(1-DataDE1c!BN86) -> 38581.527 | U63: 468.7
A64: 1924 | B64: =D64*1.95583*TableDE15a!C63/TableDE15a!C$149 -> 55.065401 | C64: =N64*B64 -> 121.86527 | D64: =D63*DataDE1c!C87/DataDE1c!C86 -> 246.24687 | E64: =D64*N64 -> 544.96905 | F64: =1000000*B64/R64 -> 886.6215 | G64: =1000000*C64/R64 -> 1962.1824 | H64: =1000000*B64/S64 -> 1405.4981 | I64: =1000000*C64/S64 -> 3110.5086 | J64: =1000000*D64/R64 -> 3964.881 | K64: =1000000*E64/R64 -> 8774.68 | L64: =1000000*D64/S64 -> 6285.2445 | M64: =1000000*E64/S64 -> 13909.878 | N64: =TableDE5a!F64 -> 2.2131005 | R64: =DataDE1c!BK87 -> 62107 | S64: =R64*(1-DataDE1c!BN87) -> 39178.566 | U64: 468.7
A65: 1925 | B65: =DataDE1c!B88 -> 65.5139 | C65: =N65*B65 -> 150.7519 | D65: =B65*(TableDE15a!C$149/TableDE15a!C64)/1.95583 -> 267.86259 | E65: =D65*N65 -> 616.36988 | F65: =1000000*B65/R65 -> 1049.734 | G65: =1000000*C65/R65 -> 2415.5088 | H65: =1000000*B65/S65 -> 1649.1733 | I65: =1000000*C65/S65 -> 3794.8591 | J65: =1000000*D65/R65 -> 4291.9818 | K65: =1000000*E65/R65 -> 9876.1398 | L65: =1000000*D65/S65 -> 6742.8718 | M65: =1000000*E65/S65 -> 15515.803 | N65: =TableDE5a!F65 -> 2.3010675 | O65: =DataDE1c!AW88/DataDE1c!B88 -> 0.87316737 | P65: =O65*L65 -> 5887.6557 | Q65: =M65/P65 -> 2.6353109 | R65: =DataDE1c!BK88 -> 62410 | S65: =R65*(1-DataDE1c!BN88) -> 39725.297 | T65: =DataDE1c!BO88 -> 31033 | U65: 468.7
A66: 1926 | B66: =DataDE1c!B89 -> 67.777915 | C66: =N66*B66 -> 181.08441 | D66: =B66*(TableDE15a!C$149/TableDE15a!C65)/1.95583 -> 269.78427 | E66: =D66*N66 -> 720.79121 | F66: =1000000*B66/R66 -> 1078.116 | G66: =1000000*C66/R66 -> 2880.4366 | H66: =1000000*B66/S66 -> 1675.7925 | I66: =1000000*C66/S66 -> 4477.2681 | J66: =1000000*D66/R66 -> 4291.3495 | K66: =1000000*E66/R66 -> 11465.335 | L66: =1000000*D66/S66 -> 6670.3506 | M66: =1000000*E66/S66 -> 17821.388 | N66: =TableDE5a!F66 -> 2.6717318 | O66: =DataDE1c!AW89/DataDE1c!B89 -> 0.8999185 | P66: =O66*L66 -> 6002.7719 | Q66: =M66/P66 -> 2.9688597 | R66: =DataDE1c!BK89 -> 62867 | S66: =R66*(1-DataDE1c!BN89) -> 40445.291 | T66: =DataDE1c!BO89 -> 29852 | U66: 468.7
A67: 1927 | B67: =DataDE1c!B90 -> 76.393524 | C67: =N67*B67 -> 209.892 | D67: =B67*(TableDE15a!C$149/TableDE15a!C66)/1.95583 -> 297.20867 | E67: =D67*N67 -> 816.58392 | F67: =1000000*B67/R67 -> 1207.7455 | G67: =1000000*C67/R67 -> 3318.2932 | H67: =1000000*B67/S67 -> 1857.577 | I67: =1000000*C67/S67 -> 5103.712 | J67: =1000000*D67/R67 -> 4698.7285 | K67: =1000000*E67/R67 -> 12909.805 | L67: =1000000*D67/S67 -> 7226.8952 | M67: =1000000*E67/S67 -> 19855.97 | N67: =TableDE5a!F67 -> 2.7475104 | O67: =DataDE1c!AW90/DataDE1c!B90 -> 0.87169693 | P67: =O67*L67 -> 6299.6624 | Q67: =M67/P67 -> 3.1519101 | R67: =DataDE1c!BK90 -> 63253 | S67: =R67*(1-DataDE1c!BN90) -> 41125.361 | T67: =DataDE1c!BO90 -> 31963 | U67: 468.7
A68: 1928 | B68: =DataDE1c!B91 -> 81.783623 | C68: =N68*B68 -> 228.94747 | D68: =B68*(TableDE15a!C$149/TableDE15a!C67)/1.95583 -> 307.09538 | E68: =D68*N68 -> 859.69179 | F68: =1000000*B68/R68 -> 1285.5422 | G68: =1000000*C68/R68 -> 3598.7844 | H68: =1000000*B68/S68 -> 1956.6909 | I68: =1000000*C68/S68 -> 5477.6179 | J68: =1000000*D68/R68 -> 4827.1775 | K68: =1000000*E68/R68 -> 13513.342 | L68: =1000000*D68/S68 -> 7347.3236 | M68: =1000000*E68/S68 -> 20568.313 | N68: =TableDE5a!F68 -> 2.7994293 | O68: =DataDE1c!AW91/DataDE1c!B91 -> 0.8742117 | P68: =O68*L68 -> 6423.1163 | Q68: =M68/P68 -> 3.2022327 | R68: =DataDE1c!BK91 -> 63618 | S68: =R68*(1-DataDE1c!BN91) -> 41796.904 | T68: =DataDE1c!BO91 -> 32531 | U68: 468.7
A69: 1929 | B69: =DataDE1c!B92 -> 81.509642 | C69: =N69*B69 -> 248.2871 | D69: =B69*(TableDE15a!C$149/TableDE15a!C68)/1.95583 -> 300.76233 | E69: =D69*N69 -> 916.15429 | F69: =1000000*B69/R69 -> 1274.4245 | G69: =1000000*C69/R69 -> 3882.0336 | H69: =1000000*B69/S69 -> 1919.8239 | I69: =1000000*C69/S69 -> 5847.9892 | J69: =1000000*D69/R69 -> 4702.4975 | K69: =1000000*E69/R69 -> 14324.311 | L69: =1000000*D69/S69 -> 7083.9559 | M69: =1000000*E69/S69 -> 21578.489 | N69: =TableDE5a!F69 -> 3.0461071 | O69: =DataDE1c!AW92/DataDE1c!B92 -> 0.88159877 | P69: =O69*L69 -> 6245.2068 | Q69: =M69/P69 -> 3.455208 | R69: =DataDE1c!BK92 -> 63958 | S69: =R69*(1-DataDE1c!BN92) -> 42456.833 | T69: =DataDE1c!BO92 -> 32266 | U69: 468.7
A70: 1930 | B70: =DataDE1c!B93 -> 75.05359 | C70: =N70*B70 -> 240.56338 | D70: =B70*(TableDE15a!C$149/TableDE15a!C69)/1.95583 -> 277.65082 | E70: =D70*N70 -> 889.93235 | F70: =1000000*B70/R70 -> 1167.3317 | G70: =1000000*C70/R70 -> 3741.5565 | H70: =1000000*B70/S70 -> 1740.5994 | I70: =1000000*C70/S70 -> 5579.0067 | J70: =1000000*D70/R70 -> 4318.3889 | K70: =1000000*E70/R70 -> 13841.393 | L70: =1000000*D70/S70 -> 6439.1171 | M70: =1000000*E70/S70 -> 20638.796 | N70: =TableDE5a!F70 -> 3.2052214 | O70: =DataDE1c!AW93/DataDE1c!B93 -> 0.88651455 | P70: =O70*L70 -> 5708.371 | Q70: =M70/P70 -> 3.6155317 | R70: =DataDE1c!BK93 -> 64295 | S70: =R70*(1-DataDE1c!BN93) -> 43119.392 | T70: =DataDE1c!BO93 -> 30483 | U70: 468.7
A71: 1931 | B71: =DataDE1c!B94 -> 61.589965 | C71: =N71*B71 -> 207.32547 | D71: =B71*(TableDE15a!C$149/TableDE15a!C70)/1.95583 -> 241.18709 | E71: =D71*N71 -> 811.8892 | F71: =1000000*B71/R71 -> 952.94773 | G71: =1000000*C71/R71 -> 3207.8332 | H71: =1000000*B71/S71 -> 1406.6172 | I71: =1000000*C71/S71 -> 4734.9852 | J71: =1000000*D71/R71 -> 3731.7556 | K71: =1000000*E71/R71 -> 12561.916 | L71: =1000000*D71/S71 -> 5508.3311 | M71: =1000000*E71/S71 -> 18542.263 | N71: =TableDE5a!F71 -> 3.3662216 | O71: =DataDE1c!AW94/DataDE1c!B94 -> 0.9018742 | P71: =O71*L71 -> 4967.8217 | Q71: =M71/P71 -> 3.7324735 | R71: =DataDE1c!BK94 -> 64631 | S71: =R71*(1-DataDE1c!BN94) -> 43785.875 | T71: =DataDE1c!BO94 -> 28115 | U71: 468.7
A72: 1932 | B72: =DataDE1c!B95 -> 49.716754 | C72: =N72*B72 -> 173.31363 | D72: =B72*(TableDE15a!C$149/TableDE15a!C71)/1.95583 -> 220.04563 | E72: =D72*N72 -> 767.0836 | F72: =1000000*B72/R72 -> 765.91007 | G72: =1000000*C72/R72 -> 2669.9783 | H72: =1000000*B72/S72 -> 1119.26 | I72: =1000000*C72/S72 -> 3901.7635 | J72: =1000000*D72/R72 -> 3389.9069 | K72: =1000000*E72/R72 -> 11817.285 | L72: =1000000*D72/S72 -> 4953.8286 | M72: =1000000*E72/S72 -> 17269.148 | N72: =TableDE5a!F72 -> 3.4860206 | O72: =DataDE1c!AW95/DataDE1c!B95 -> 0.91340838 | P72: =O72*L72 -> 4524.8685 | Q72: =M72/P72 -> 3.8164973 | R72: =DataDE1c!BK95 -> 64912 | S72: =R72*(1-DataDE1c!BN95) -> 44419.307 | T72: =DataDE1c!BO95 -> 26113 | U72: 468.7
A73: 1933 | B73: =DataDE1c!B96 -> 51.2088 | C73: =N73*B73 -> 169.63802 | D73: =B73*(TableDE15a!C$149/TableDE15a!C72)/1.95583 -> 237.16199 | E73: =D73*N73 -> 785.64018 | F73: =1000000*B73/R73 -> 785.11 | G73: =1000000*C73/R73 -> 2600.8129 | H73: =1000000*B73/S73 -> 1135.9868 | I73: =1000000*C73/S73 -> 3763.1532 | J73: =1000000*D73/R73 -> 3636.0597 | K73: =1000000*E73/R73 -> 12045.077 | L73: =1000000*D73/S73 -> 5261.0665 | M73: =1000000*E73/S73 -> 17428.194 | N73: =TableDE5a!F73 -> 3.3126732 | O73: =DataDE1c!AW96/DataDE1c!B96 -> 0.89933761 | P73: =O73*L73 -> 4731.475 | Q73: =M73/P73 -> 3.683459 | R73: =DataDE1c!BK96 -> 65225 | S73: =R73*(1-DataDE1c!BN96) -> 45078.691 | T73: =DataDE1c!BO96 -> 26687 | U73: 468.8
...

Sheet TableDE2
B1: Back to index
A3: Table DE.2: National income and private wealth in Germany, 1870-2010 (decennial averages)
B5: [1] | C5: [2] | D5: [3] | E5: [4] | F5: [5] | G5: [6] | H5: [7] | I5: [8] | J5: [9] | K5: [10] | L5: [11] | M5: [12] | N5: [13] | O5: [14] | P5: [15] | Q5: [16] | R5: [17] | S5: [18] | T5: [19]
B6: Boundaries: 1870-1944: German Empire (including Alsace-Lorraine from 1871 on, excluding territories lost in the wake of World War 1 from 1919-1923 on, including Saarland from 1935 on, and including annexed territories in 1938-1944); 1945-1949: territory occupied by the Allied powers and USSR; 1950-1990: West Germany (including Saarland & West Berlin); 1991-onwards: reunified Germany.
B7: (current billions euros 1950-2010; current billions marks 1850-1949) | D7: (2010 billions euros) | F7: (current euros 1950-2010; current marks 1850-1949) | J7: (2010 euros) | N7: Ratio (private wealth)/ (national income) βt = Wt/Yt | O7: memo: Ratio (dispos. income)/ (national income) | P7: memo: Per adult dispos. income (2010 €) | Q7: memo: Ratio (private wealth)/ (dispos. income) | R7: Population (thousands) | S7: Adult population (20-yr+) | T7: Employed population
B8: National income Yt | C8: Private wealth Wt | D8: National income Yt | E8: Private wealth Wt | F8: Per capita national income | G8: Per capita private wealth | H8: Per adult national income yt | I8: Per adult private wealth wt | J8: Per capita national income | K8: Per capita private wealth | L8: Per adult national income yt | M8: Per adult private wealth wt
R9: Nt | S9: Nt20+ | T9: Lt
A10: 1870 | B10: =AVERAGE(TableDE1!B10:B19) -> 16.913 | C10: =AVERAGE(TableDE1!C10:C19) -> 108.36457 | D10: =AVERAGE(TableDE1!D10:D19) -> 113.48918 | E10: =AVERAGE(TableDE1!E10:E19) -> 728.3898 | F10: =AVERAGE(TableDE1!F10:F19) -> 399.46028 | G10: =AVERAGE(TableDE1!G10:G19) -> 2561.403 | H10: =AVERAGE(TableDE1!H10:H19) -> 699.15322 | I10: =AVERAGE(TableDE1!I10:I19) -> 4483.7612 | ... T10: =AVERAGE(TableDE1!T10:T19) -> 18382.55
A11: =A10+1 -> 1871 | B11: =#REF! -> #REF! | C11: =#REF! -> #REF! | F11: =1000000*B11/R11 -> #REF! | G11: =1000000*C11/R11 -> #REF! | H11: =1000000*B11/S11 -> #REF! | I11: =1000000*C11/S11 -> #REF! | J11: =1000000*D11/R11 -> #DIV/0! | K11: =1000000*E11/R11 -> #DIV/0! | L11: =1000000*D11/S11 -> #DIV/0! | M11: =1000000*E11/S11 -> #DIV/0! | N11: =AVERAGE(TableDE1!N11:N20) -> 6.3812506 | O11: =AVERAGE(TableDE1!O11:O20) -> 0.95712718 | P11: =AVERAGE(TableDE1!P11:P20) -> 4508.0953 | Q11: =AVERAGE(TableDE1!Q11:Q20) -> 6.6675932 | R11: 0 | S11: 0 | T11: 0
A12: =A11+1 -> 1872 | B12: =#REF! -> #REF! | C12: =#REF! -> #REF! | F12: =1000000*B12/R12 -> #REF! | G12: =1000000*C12/R12 -> #REF! | H12: =1000000*B12/S12 -> #REF! | I12: =1000000*C12/S12 -> #REF! | J12: =1000000*D12/R12 -> #DIV/0! | K12: =1000000*E12/R12 -> #DIV/0! | L12: =1000000*D12/S12 -> #DIV/0! | M12: =1000000*E12/S12 -> #DIV/0! | N12: =AVERAGE(TableDE1!N12:N21) -> 6.3331177 | O12: =AVERAGE(TableDE1!O12:O21) -> 0.95628731 | P12: =AVERAGE(TableDE1!P12:P21) -> 4538.4644 | Q12: =AVERAGE(TableDE1!Q12:Q21) -> 6.6232348 | R12: 0 | S12: 0 | T12: 0
A13: =A12+1 -> 1873 | B13: =#REF! -> #REF! | C13: =#REF! -> #REF! | F13: =1000000*B13/R13 -> #REF! | G13: =1000000*C13/R13 -> #REF! | H13: =1000000*B13/S13 -> #REF! | I13: =1000000*C13/S13 -> #REF! | J13: =1000000*D13/R13 -> #DIV/0! | K13: =1000000*E13/R13 -> #DIV/0! | L13: =1000000*D13/S13 -> #DIV/0! | M13: =1000000*E13/S13 -> #DIV/0! | N13: =AVERAGE(TableDE1!N13:N22) -> 6.3531009 | O13: =AVERAGE(TableDE1!O13:O22) -> 0.95478818 | P13: =AVERAGE(TableDE1!P13:P22) -> 4524.2722 | Q13: =AVERAGE(TableDE1!Q13:Q22) -> 6.6546465 | R13: 0 | S13: 0 | T13: 0
A14: =A13+1 -> 1874 | B14: =#REF! -> #REF! | C14: =#REF! -> #REF! | F14: =1000000*B14/R14 -> #REF! | G14: =1000000*C14/R14 -> #REF! | H14: =1000000*B14/S14 -> #REF! | I14: =1000000*C14/S14 -> #REF! | J14: =1000000*D14/R14 -> #DIV/0! | K14: =1000000*E14/R14 -> #DIV/0! | L14: =1000000*D14/S14 -> #DIV/0! | M14: =1000000*E14/S14 -> #DIV/0! | N14: =AVERAGE(TableDE1!N14:N23) -> 6.3607618 | O14: =AVERAGE(TableDE1!O14:O23) -> 0.95422474 | P14: =AVERAGE(TableDE1!P14:P23) -> 4531.5132 | Q14: =AVERAGE(TableDE1!Q14:Q23) -> 6.666609 | R14: 0 | S14: 0 | T14: 0
A15: =A14+1 -> 1875 | B15: =#REF! -> #REF! | C15: =#REF! -> #REF! | F15: =1000000*B15/R15 -> #REF! | G15: =1000000*C15/R15 -> #REF! | H15: =1000000*B15/S15 -> #REF! | I15: =1000000*C15/S15 -> #REF! | J15: =1000000*D15/R15 -> #DIV/0! | K15: =1000000*E15/R15 -> #DIV/0! | L15: =1000000*D15/S15 -> #DIV/0! | M15: =1000000*E15/S15 -> #DIV/0! | N15: =AVERAGE(TableDE1!N15:N24) -> 6.3875289 | O15: =AVERAGE(TableDE1!O15:O24) -> 0.95340156 | P15: =AVERAGE(TableDE1!P15:P24) -> 4521.7391 | Q15: =AVERAGE(TableDE1!Q15:Q24) -> 6.7000831 | R15: 0 | S15: 0 | T15: 0
A16: =A15+1 -> 1876 | B16: =#REF! -> #REF! | C16: =#REF! -> #REF! | F16: =1000000*B16/R16 -> #REF! | G16: =1000000*C16/R16 -> #REF! | H16: =1000000*B16/S16 -> #REF! | I16: =1000000*C16/S16 -> #REF! | J16: =1000000*D16/R16 -> #DIV/0! | K16: =1000000*E16/R16 -> #DIV/0! | L16: =1000000*D16/S16 -> #DIV/0! | M16: =1000000*E16/S16 -> #DIV/0! | N16: =AVERAGE(TableDE1!N16:N25) -> 6.3875192 | O16: =AVERAGE(TableDE1!O16:O25) -> 0.95292093 | P16: =AVERAGE(TableDE1!P16:P25) -> 4538.652 | Q16: =AVERAGE(TableDE1!Q16:Q25) -> 6.7034239 | R16: 0 | S16: 0 | T16: 0
A17: =A16+1 -> 1877 | B17: =#REF! -> #REF! | C17: =#REF! -> #REF! | F17: =1000000*B17/R17 -> #REF! | G17: =1000000*C17/R17 -> #REF! | H17: =1000000*B17/S17 -> #REF! | I17: =1000000*C17/S17 -> #REF! | J17: =1000000*D17/R17 -> #DIV/0! | K17: =1000000*E17/R17 -> #DIV/0! | L17: =1000000*D17/S17 -> #DIV/0! | M17: =1000000*E17/S17 -> #DIV/0! | N17: =AVERAGE(TableDE1!N17:N26) -> 6.4020054 | O17: =AVERAGE(TableDE1!O17:O26) -> 0.95189054 | P17: =AVERAGE(TableDE1!P17:P26) -> 4568.5792 | Q17: =AVERAGE(TableDE1!Q17:Q26) -> 6.7259428 | R17: 0 | S17: 0 | T17: 0
A18: =A17+1 -> 1878 | B18: =#REF! -> #REF! | C18: =#REF! -> #REF! | F18: =1000000*B18/R18 -> #REF! | G18: =1000000*C18/R18 -> #REF! | H18: =1000000*B18/S18 -> #REF! | I18: =1000000*C18/S18 -> #REF! | J18: =1000000*D18/R18 -> #DIV/0! | K18: =1000000*E18/R18 -> #DIV/0! | L18: =1000000*D18/S18 -> #DIV/0! | M18: =1000000*E18/S18 -> #DIV/0! | N18: =AVERAGE(TableDE1!N18:N27) -> 6.4260041 | O18: =AVERAGE(TableDE1!O18:O27) -> 0.95130919 | P18: =AVERAGE(TableDE1!P18:P27) -> 4611.1004 | Q18: =AVERAGE(TableDE1!Q18:Q27) -> 6.75526 | R18: 0 | S18: 0 | T18: 0
A19: =A18+1 -> 1879 | B19: =#REF! -> #REF! | C19: =#REF! -> #REF! | F19: =1000000*B19/R19 -> #REF! | G19: =1000000*C19/R19 -> #REF! | H19: =1000000*B19/S19 -> #REF! | I19: =1000000*C19/S19 -> #REF! | J19: =1000000*D19/R19 -> #DIV/0! | K19: =1000000*E19/R19 -> #DIV/0! | L19: =1000000*D19/S19 -> #DIV/0! | M19: =1000000*E19/S19 -> #DIV/0! | N19: =AVERAGE(TableDE1!N19:N28) -> 6.4595382 | O19: =AVERAGE(TableDE1!O19:O28) -> 0.95054313 | P19: =AVERAGE(TableDE1!P19:P28) -> 4655.9889 | Q19: =AVERAGE(TableDE1!Q19:Q28) -> 6.7957666 | R19: 0 | S19: 0 | T19: 0
A20: 1880 | B20: =AVERAGE(TableDE1!B20:B29) -> 18.8293 | C20: =AVERAGE(TableDE1!C20:C29) -> 121.30621 | D20: =AVERAGE(TableDE1!D20:D29) -> 135.25176 | E20: =AVERAGE(TableDE1!E20:E29) -> 871.45998 | F20: =AVERAGE(TableDE1!F20:F29) -> 402.72702 | G20: =AVERAGE(TableDE1!G20:G29) -> 2594.4591 | H20: =AVERAGE(TableDE1!H20:H29) -> 694.32218 | I20: =AVERAGE(TableDE1!I20:I29) -> 4472.981 | ... T20: =AVERAGE(TableDE1!T20:T29) -> 20647
A21: =A20+1 -> 1881 | B21: =#REF! -> #REF! | C21: =#REF! -> #REF! | F21: =1000000*B21/R21 -> #REF! | G21: =1000000*C21/R21 -> #REF! | H21: =1000000*B21/S21 -> #REF! | I21: =1000000*C21/S21 -> #REF! | J21: =1000000*D21/R21 -> #DIV/0! | K21: =1000000*E21/R21 -> #DIV/0! | L21: =1000000*D21/S21 -> #DIV/0! | M21: =1000000*E21/S21 -> #DIV/0! | N21: =AVERAGE(TableDE1!N21:N30) -> 6.4196179 | O21: =AVERAGE(TableDE1!O21:O30) -> 0.94991445 | P21: =AVERAGE(TableDE1!P21:P30) -> 4850.8141 | Q21: =AVERAGE(TableDE1!Q21:Q30) -> 6.7581658 | R21: 0 | S21: 0 | T21: 0
A22: =A21+1 -> 1882 | B22: =#REF! -> #REF! | C22: =#REF! -> #REF! | F22: =1000000*B22/R22 -> #REF! | G22: =1000000*C22/R22 -> #REF! | H22: =1000000*B22/S22 -> #REF! | I22: =1000000*C22/S22 -> #REF! | J22: =1000000*D22/R22 -> #DIV/0! | K22: =1000000*E22/R22 -> #DIV/0! | L22: =1000000*D22/S22 -> #DIV/0! | M22: =1000000*E22/S22 -> #DIV/0! | N22: =AVERAGE(TableDE1!N22:N31) -> 6.4329161 | O22: =AVERAGE(TableDE1!O22:O31) -> 0.94967189 | P22: =AVERAGE(TableDE1!P22:P31) -> 4922.5939 | Q22: =AVERAGE(TableDE1!Q22:Q31) -> 6.7739536 | R22: 0 | S22: 0 | T22: 0
A23: =A22+1 -> 1883 | B23: =#REF! -> #REF! | C23: =#REF! -> #REF! | F23: =1000000*B23/R23 -> #REF! | G23: =1000000*C23/R23 -> #REF! | H23: =1000000*B23/S23 -> #REF! | I23: =1000000*C23/S23 -> #REF! | J23: =1000000*D23/R23 -> #DIV/0! | K23: =1000000*E23/R23 -> #DIV/0! | L23: =1000000*D23/S23 -> #DIV/0! | M23: =1000000*E23/S23 -> #DIV/0! | N23: =AVERAGE(TableDE1!N23:N32) -> 6.3867099 | O23: =AVERAGE(TableDE1!O23:O32) -> 0.94999668 | P23: =AVERAGE(TableDE1!P23:P32) -> 5023.8799 | Q23: =AVERAGE(TableDE1!Q23:Q32) -> 6.7230477 | R23: 0 | S23: 0 | T23: 0
A24: =A23+1 -> 1884 | B24: =#REF! -> #REF! | C24: =#REF! -> #REF! | F24: =1000000*B24/R24 -> #REF! | G24: =1000000*C24/R24 -> #REF! | H24: =1000000*B24/S24 -> #REF! | I24: =1000000*C24/S24 -> #REF! | J24: =1000000*D24/R24 -> #DIV/0! | K24: =1000000*E24/R24 -> #DIV/0! | L24: =1000000*D24/S24 -> #DIV/0! | M24: =1000000*E24/S24 -> #DIV/0! | N24: =AVERAGE(TableDE1!N24:N33) -> 6.3375044 | O24: =AVERAGE(TableDE1!O24:O33) -> 0.94998298 | P24: =AVERAGE(TableDE1!P24:P33) -> 5135.5615 | Q24: =AVERAGE(TableDE1!Q24:Q33) -> 6.671443 | R24: 0 | S24: 0 | T24: 0
A25: =A24+1 -> 1885 | B25: =#REF! -> #REF! | C25: =#REF! -> #REF! | F25: =1000000*B25/R25 -> #REF! | G25: =1000000*C25/R25 -> #REF! | H25: =1000000*B25/S25 -> #REF! | I25: =1000000*C25/S25 -> #REF! | J25: =1000000*D25/R25 -> #DIV/0! | K25: =1000000*E25/R25 -> #DIV/0! | L25: =1000000*D25/S25 -> #DIV/0! | M25: =1000000*E25/S25 -> #DIV/0! | N25: =AVERAGE(TableDE1!N25:N34) -> 6.3091588 | O25: =AVERAGE(TableDE1!O25:O34) -> 0.9494329 | P25: =AVERAGE(TableDE1!P25:P34) -> 5223.7953 | Q25: =AVERAGE(TableDE1!Q25:Q34) -> 6.6453619 | R25: 0 | S25: 0 | T25: 0
A26: =A25+1 -> 1886 | B26: =#REF! -> #REF! | C26: =#REF! -> #REF! | F26: =1000000*B26/R26 -> #REF! | G26: =1000000*C26/R26 -> #REF! | H26: =1000000*B26/S26 -> #REF! | I26: =1000000*C26/S26 -> #REF! | J26: =1000000*D26/R26 -> #DIV/0! | K26: =1000000*E26/R26 -> #DIV/0! | L26: =1000000*D26/S26 -> #DIV/0! | M26: =1000000*E26/S26 -> #DIV/0! | N26: =AVERAGE(TableDE1!N26:N35) -> 6.2526996 | O26: =AVERAGE(TableDE1!O26:O35) -> 0.94899289 | P26: =AVERAGE(TableDE1!P26:P35) -> 5317.499 | Q26: =AVERAGE(TableDE1!Q26:Q35) -> 6.5890428 | R26: 0 | S26: 0 | T26: 0
A27: =A26+1 -> 1887 | B27: =#REF! -> #REF! | C27: =#REF! -> #REF! | F27: =1000000*B27/R27 -> #REF! | G27: =1000000*C27/R27 -> #REF! | H27: =1000000*B27/S27 -> #REF! | I27: =1000000*C27/S27 -> #REF! | J27: =1000000*D27/R27 -> #DIV/0! | K27: =1000000*E27/R27 -> #DIV/0! | L27: =1000000*D27/S27 -> #DIV/0! | M27: =1000000*E27/S27 -> #DIV/0! | N27: =AVERAGE(TableDE1!N27:N36) -> 6.1671227 | O27: =AVERAGE(TableDE1!O27:O36) -> 0.94908377 | P27: =AVERAGE(TableDE1!P27:P36) -> 5430.6987 | Q27: =AVERAGE(TableDE1!Q27:Q36) -> 6.4981721 | R27: 0 | S27: 0 | T27: 0
A28: =A27+1 -> 1888 | B28: =#REF! -> #REF! | C28: =#REF! -> #REF! | F28: =1000000*B28/R28 -> #REF! | G28: =1000000*C28/R28 -> #REF! | H28: =1000000*B28/S28 -> #REF! | I28: =1000000*C28/S28 -> #REF! | J28: =1000000*D28/R28 -> #DIV/0! | K28: =1000000*E28/R28 -> #DIV/0! | L28: =1000000*D28/S28 -> #DIV/0! | M28: =1000000*E28/S28 -> #DIV/0! | N28: =AVERAGE(TableDE1!N28:N37) -> 6.0658991 | O28: =AVERAGE(TableDE1!O28:O37) -> 0.94890736 | P28: =AVERAGE(TableDE1!P28:P37) -> 5555.241 | Q28: =AVERAGE(TableDE1!Q28:Q37) -> 6.3928724 | R28: 0 | S28: 0 | T28: 0
A29: =A28+1 -> 1889 | B29: =#REF! -> #REF! | C29: =#REF! -> #REF! | F29: =1000000*B29/R29 -> #REF! | G29: =1000000*C29/R29 -> #REF! | H29: =1000000*B29/S29 -> #REF! | I29: =1000000*C29/S29 -> #REF! | J29: =1000000*D29/R29 -> #DIV/0! | K29: =1000000*E29/R29 -> #DIV/0! | L29: =1000000*D29/S29 -> #DIV/0! | M29: =1000000*E29/S29 -> #DIV/0! | N29: =AVERAGE(TableDE1!N29:N38) -> 5.9734288 | O29: =AVERAGE(TableDE1!O29:O38) -> 0.94883483 | P29: =AVERAGE(TableDE1!P29:P38) -> 5694.0898 | Q29: =AVERAGE(TableDE1!Q29:Q38) -> 6.2959186 | R29: 0 | S29: 0 | T29: 0
A30: 1890 | B30: =AVERAGE(TableDE1!B30:B39) -> 26.2092 | C30: =AVERAGE(TableDE1!C30:C39) -> 154.5943 | D30: =AVERAGE(TableDE1!D30:D39) -> 185.55855 | E30: =AVERAGE(TableDE1!E30:E39) -> 1094.0361 | F30: =AVERAGE(TableDE1!F30:F39) -> 503.29726 | G30: =AVERAGE(TableDE1!G30:G39) -> 2972.7955 | H30: =AVERAGE(TableDE1!H30:H39) -> 862.92048 | I30: =AVERAGE(TableDE1!I30:I39) -> 5097.5798 | ... T30: =AVERAGE(TableDE1!T30:T39) -> 23464
A31: =A30+1 -> 1891 | B31: =#REF! -> #REF! | C31: =#REF! -> #REF! | F31: =1000000*B31/R31 -> #REF! | G31: =1000000*C31/R31 -> #REF! | H31: =1000000*B31/S31 -> #REF! | I31: =1000000*C31/S31 -> #REF! | J31: =1000000*D31/R31 -> #DIV/0! | K31: =1000000*E31/R31 -> #DIV/0! | L31: =1000000*D31/S31 -> #DIV/0! | M31: =1000000*E31/S31 -> #DIV/0! | N31: =AVERAGE(TableDE1!N31:N40) -> 5.9150984 | O31: =AVERAGE(TableDE1!O31:O40) -> 0.9488329 | P31: =AVERAGE(TableDE1!P31:P40) -> 5871.0184 | Q31: =AVERAGE(TableDE1!Q31:Q40) -> 6.2343412 | R31: 0 | S31: 0 | T31: 0
A32: =A31+1 -> 1892 | B32: =#REF! -> #REF! | C32: =#REF! -> #REF! | F32: =1000000*B32/R32 -> #REF! | G32: =1000000*C32/R32 -> #REF! | H32: =1000000*B32/S32 -> #REF! | I32: =1000000*C32/S32 -> #REF! | J32: =1000000*D32/R32 -> #DIV/0! | K32: =1000000*E32/R32 -> #DIV/0! | L32: =1000000*D32/S32 -> #DIV/0! | M32: =1000000*E32/S32 -> #DIV/0! | N32: =AVERAGE(TableDE1!N32:N41) -> 5.9077794 | O32: =AVERAGE(TableDE1!O32:O41) -> 0.94863969 | P32: =AVERAGE(TableDE1!P32:P41) -> 5958.9239 | Q32: =AVERAGE(TableDE1!Q32:Q41) -> 6.2280064 | R32: 0 | S32: 0 | T32: 0
A33: =A32+1 -> 1893 | B33: =#REF! -> #REF! | C33: =#REF! -> #REF! | F33: =1000000*B33/R33 -> #REF! | G33: =1000000*C33/R33 -> #REF! | H33: =1000000*B33/S33 -> #REF! | I33: =1000000*C33/S33 -> #REF! | J33: =1000000*D33/R33 -> #DIV/0! | K33: =1000000*E33/R33 -> #DIV/0! | L33: =1000000*D33/S33 -> #DIV/0! | M33: =1000000*E33/S33 -> #DIV/0! | N33: =AVERAGE(TableDE1!N33:N42) -> 5.9384874 | O33: =AVERAGE(TableDE1!O33:O42) -> 0.94798776 | P33: =AVERAGE(TableDE1!P33:P42) -> 6020.6833 | Q33: =AVERAGE(TableDE1!Q33:Q42) -> 6.2648819 | R33: 0 | S33: 0 | T33: 0
A34: =A33+1 -> 1894 | B34: =#REF! -> #REF! | C34: =#REF! -> #REF! | F34: =1000000*B34/R34 -> #REF! | G34: =1000000*C34/R34 -> #REF! | H34: =1000000*B34/S34 -> #REF! | I34: =1000000*C34/S34 -> #REF! | J34: =1000000*D34/R34 -> #DIV/0! | K34: =1000000*E34/R34 -> #DIV/0! | L34: =1000000*D34/S34 -> #DIV/0! | M34: =1000000*E34/S34 -> #DIV/0! | N34: =AVERAGE(TableDE1!N34:N43) -> 5.9506844 | O34: =AVERAGE(TableDE1!O34:O43) -> 0.94757875 | P34: =AVERAGE(TableDE1!P34:P43) -> 6083.3375 | Q34: =AVERAGE(TableDE1!Q34:Q43) -> 6.2804358 | R34: 0 | S34: 0 | T34: 0
A35: =A34+1 -> 1895 | B35: =#REF! -> #REF! | C35: =#REF! -> #REF! | F35: =1000000*B35/R35 -> #REF! | G35: =1000000*C35/R35 -> #REF! | H35: =1000000*B35/S35 -> #REF! | I35: =1000000*C35/S35 -> #REF! | J35: =1000000*D35/R35 -> #DIV/0! | K35: =1000000*E35/R35 -> #DIV/0! | L35: =1000000*D35/S35 -> #DIV/0! | M35: =1000000*E35/S35 -> #DIV/0! | N35: =AVERAGE(TableDE1!N35:N44) -> 5.9497777 | O35: =AVERAGE(TableDE1!O35:O44) -> 0.94770547 | P35: =AVERAGE(TableDE1!P35:P44) -> 6175.2501 | Q35: =AVERAGE(TableDE1!Q35:Q44) -> 6.278636 | R35: 0 | S35: 0 | T35: 0
A36: =A35+1 -> 1896 | B36: =#REF! -> #REF! | C36: =#REF! -> #REF! | F36: =1000000*B36/R36 -> #REF! | G36: =1000000*C36/R36 -> #REF! | H36: =1000000*B36/S36 -> #REF! | I36: =1000000*C36/S36 -> #REF! | J36: =1000000*D36/R36 -> #DIV/0! | K36: =1000000*E36/R36 -> #DIV/0! | L36: =1000000*D36/S36 -> #DIV/0! | M36: =1000000*E36/S36 -> #DIV/0! | N36: =AVERAGE(TableDE1!N36:N45) -> 5.9533852 | O36: =AVERAGE(TableDE1!O36:O45) -> 0.94742429 | P36: =AVERAGE(TableDE1!P36:P45) -> 6270.6678 | Q36: =AVERAGE(TableDE1!Q36:Q45) -> 6.2842617 | R36: 0 | S36: 0 | T36: 0
A37: =A36+1 -> 1897 | B37: =#REF! -> #REF! | C37: =#REF! -> #REF! | F37: =1000000*B37/R37 -> #REF! | G37: =1000000*C37/R37 -> #REF! | H37: =1000000*B37/S37 -> #REF! | I37: =1000000*C37/S37 -> #REF! | J37: =1000000*D37/R37 -> #DIV/0! | K37: =1000000*E37/R37 -> #DIV/0! | L37: =1000000*D37/S37 -> #DIV/0! | M37: =1000000*E37/S37 -> #DIV/0! | N37: =AVERAGE(TableDE1!N37:N46) -> 5.9878823 | O37: =AVERAGE(TableDE1!O37:O46) -> 0.94717867 | P37: =AVERAGE(TableDE1!P37:P46) -> 6333.9067 | Q37: =AVERAGE(TableDE1!Q37:Q46) -> 6.3222713 | R37: 0 | S37: 0 | T37: 0
A38: =A37+1 -> 1898 | B38: =#REF! -> #REF! | C38: =#REF! -> #REF! | F38: =1000000*B38/R38 -> #REF! | G38: =1000000*C38/R38 -> #REF! | H38: =1000000*B38/S38 -> #REF! | I38: =1000000*C38/S38 -> #REF! | J38: =1000000*D38/R38 -> #DIV/0! | K38: =1000000*E38/R38 -> #DIV/0! | L38: =1000000*D38/S38 -> #DIV/0! | M38: =1000000*E38/S38 -> #DIV/0! | N38: =AVERAGE(TableDE1!N38:N47) -> 6.0232462 | O38: =AVERAGE(TableDE1!O38:O47) -> 0.94669361 | P38: =AVERAGE(TableDE1!P38:P47) -> 6413.5414 | Q38: =AVERAGE(TableDE1!Q38:Q47) -> 6.3627513 | R38: 0 | S38: 0 | T38: 0
A39: =A38+1 -> 1899 | B39: =#REF! -> #REF! | C39: =#REF! -> #REF! | F39: =1000000*B39/R39 -> #REF! | G39: =1000000*C39/R39 -> #REF! | H39: =1000000*B39/S39 -> #REF! | I39: =1000000*C39/S39 -> #REF! | J39: =1000000*D39/R39 -> #DIV/0! | K39: =1000000*E39/R39 -> #DIV/0! | L39: =1000000*D39/S39 -> #DIV/0! | M39: =1000000*E39/S39 -> #DIV/0! | N39: =AVERAGE(TableDE1!N39:N48) -> 6.0930333 | O39: =AVERAGE(TableDE1!O39:O48) -> 0.94607999 | P39: =AVERAGE(TableDE1!P39:P48) -> 6447.5503 | Q39: =AVERAGE(TableDE1!Q39:Q48) -> 6.4406106 | R39: 0 | S39: 0 | T39: 0
A40: 1900 | B40: =AVERAGE(TableDE1!B40:B49) -> 37.4087 | C40: =AVERAGE(TableDE1!C40:C49) -> 228.2181 | D40: =AVERAGE(TableDE1!D40:D49) -> 238.92006 | E40: =AVERAGE(TableDE1!E40:E49) -> 1458.2072 | F40: =AVERAGE(TableDE1!F40:F49) -> 622.63904 | G40: =AVERAGE(TableDE1!G40:G49) -> 3800.3762 | H40: =AVERAGE(TableDE1!H40:H49) -> 1077.5525 | I40: =AVERAGE(TableDE1!I40:I49) -> 6576.2982 | ... T40: =AVERAGE(TableDE1!T40:T49) -> 27045
A41: =A40+1 -> 1901 | B41: =#REF! -> #REF! | C41: =#REF! -> #REF! | E41: =C41*(TableDE15a!$B$149/AVERAGE(TableDE15a!$B$39:$B$48))/1.95583 -> #REF! | F41: =1000000*B41/R41 -> #REF! | G41: =1000000*C41/R41 -> #REF! | H41: =1000000*B41/S41 -> #REF! | I41: =1000000*C41/S41 -> #REF! | J41: =1000000*D41/R41 -> #REF! | K41: =1000000*E41/R41 -> #REF! | L41: =1000000*D41/S41 -> #REF! | M41: =1000000*E41/S41 -> #REF! | N41: =AVERAGE(TableDE1!N41:N50) -> 6.1061585 | O41: =AVERAGE(TableDE1!O41:O50) -> 0.94354143 | P41: =AVERAGE(TableDE1!P41:P50) -> 6575.5125 | Q41: =AVERAGE(TableDE1!Q41:Q50) -> 6.4718311 | R41: =AVERAGE(#REF!) -> #REF! | S41: =AVERAGE(#REF!) -> #REF! | T41: =AVERAGE(#REF!) -> #REF!
A42: =A41+1 -> 1902 | B42: =#REF! -> #REF! | C42: =#REF! -> #REF! | E42: =C42*(TableDE15a!$B$149/AVERAGE(TableDE15a!$B$39:$B$48))/1.95583 -> #REF! | F42: =1000000*B42/R42 -> #REF! | G42: =1000000*C42/R42 -> #REF! | H42: =1000000*B42/S42 -> #REF! | I42: =1000000*C42/S42 -> #REF! | J42: =1000000*D42/R42 -> #REF! | K42: =1000000*E42/R42 -> #REF! | L42: =1000000*D42/S42 -> #REF! | M42: =1000000*E42/S42 -> #REF! | N42: =AVERAGE(TableDE1!N42:N51) -> 6.0633699 | O42: =AVERAGE(TableDE1!O42:O51) -> 0.94197872 | P42: =AVERAGE(TableDE1!P42:P51) -> 6679.2307 | Q42: =AVERAGE(TableDE1!Q42:Q51) -> 6.437295 | R42: =AVERAGE(#REF!) -> #REF! | S42: =AVERAGE(#REF!) -> #REF! | T42: =AVERAGE(#REF!) -> #REF!
...

Sheet TableDE3
B1: Back to index
A3: Table DE.3: Economic growth, population growth and price deflators in Germany (changing boundaries), 1870-2010
B5: [1] | C5: [2] | D5: [3] | E5: [4] | F5: [5] | G5: [6] | H5: [7] | I5: [8] | J5: [9] | K5: [10] | L5: [11]
B6: Boundaries: 1870-1944: German Empire (including Alsace-Lorraine from 1871 on, excluding territories lost in the wake of World War 1 from 1919-1923 on, including Saarland from 1935 on, and including annexed territories in 1938-1944); 1945-1949: territory occupied by the Allied powers and USSR; 1950-1990: West Germany (including Saarland & West Berlin); 1991-onwards: reunified Germany.
B7: Real growth rate of national income (GDP deflator) | C7: Real growth rate of private wealth (GDP deflator) | D7: Real growth rate of per-capita national income (GDP deflator) | E7: Real growth rate of per-capita national income (CPI) | F7: Real growth rate of per-employed national income (GDP deflator) | G7: Population growth rate | H7: Adult population growth rate (20-yr+) | I7: Employed population growth rate | J7: GDP price inflation | K7: Consumer price inflation | L7: Personal consumption expenditure inflation
A8: 1870-2010 | B8: =(((1+B11)^40)*((1+B14)^100))^(1/140)-1 -> 0.022530911 | C8: =(((1+C11)^40)*((1+C14)^100))^(1/140)-1 -> 0.018623324 | D8: =(1+B8)/(1+G8)-1 -> 0.017180119 | E8: =(1+D8)*(1+J8)/(1+K8)-1 -> 0.017261465 | F8: =(1+D8)*(1+G8)/(1+I8)-1 -> 0.016220097 | G8: =(((1+G11)^40)*((1+G14)^100))^(1/140)-1 -> 0.0052604175 | H8: =(((1+H11)^40)*((1+H14)^100))^(1/140)-1 -> 0.0078972157 | I8: =(((1+I11)^40)*((1+I14)^100))^(1/140)-1 -> 0.0062100854 | J8: =(((1+J11)^40)*((1+J14)^100))^(1/140)-1 -> 0.019236402 | K8: =(((1+K11)^40)*((1+K14)^100))^(1/140)-1 -> 0.019154897
A11: 1870-1910 | B11: =(TableDE1!D50/TableDE1!D10)^(1/40)-1 -> 0.026119956 | C11: =(TableDE1!E50/TableDE1!E10)^(1/40)-1 -> 0.022379243 | D11: =(1+B11)/(1+G11)-1 -> 0.013417583 | E11: =(1+D11)*(1+J11)/(1+K11)-1 -> 0.0101636 | F11: =(1+D11)*(1+G11)/(1+I11)-1 -> 0.012213933 | G11: =(TableDE1!R50/TableDE1!R10)^(1/40)-1 -> 0.012534195 | H11: =(TableDE1!S50/TableDE1!S10)^(1/40)-1 -> 0.012668325 | I11: =(TableDE1!T50/TableDE1!T10)^(1/40)-1 -> 0.013738226 | J11: =(TableDE15a!C49/TableDE15a!C9)^(1/40)-1 -> 0.0058343466 | K11: =(TableDE15a!B49/TableDE15a!B9)^(1/40)-1 -> 0.0090743844
A14: 1910-2010 | B14: =(((1+B17)^40)*((1+B20)^60))^(1/100)-1 -> 0.02109881 | C14: =(((1+C17)^40)*((1+C20)^60))^(1/100)-1 -> 0.017124823 | D14: =(1+B14)/(1+G14)-1 -> 0.018689041 | E14: =(1+D14)*(1+J14)/(1+K14)-1 -> 0.020114557 | F14: =(1+D14)*(1+G14)/(1+I14)-1 -> 0.017826999 | G14: =(((1+G17)^40)*((1+G20)^60))^(1/100)-1 -> 0.0023655585 | H14: =(((1+H17)^40)*((1+H20)^60))^(1/100)-1 -> 0.005995072 | I14: =(((1+I17)^40)*((1+I20)^60))^(1/100)-1 -> 0.0032145059 | J14: =(TableDE15a!C149/TableDE15a!C49)^(1/100)-1 -> 0.024647092 | K14: =(TableDE15a!B149/TableDE15a!B49)^(1/100)-1 -> 0.023215243
A17: 1910-1950 | B17: =(TableDE1!D90/TableDE1!D50)^(1/40)-1 -> 0.0012573723 | C17: =(TableDE1!E90/TableDE1!E50)^(1/40)-1 -> -0.028607721 | D17: =(1+B17)/(1+G17)-1 -> 0.0073045109 | E17: =(1+D17)*(1+J17)/(1+K17)-1 -> 0.0078224941 | F17: =(1+D17)*(1+G17)/(1+I17)-1 -> 0.010063107 | G17: =(TableDE1!R90/TableDE1!R50)^(1/40)-1 -> -0.0060032875 | H17: =(TableDE1!S90/TableDE1!S50)^(1/40)-1 -> -0.00098270663 | I17: =(TableDE1!T90/TableDE1!T50)^(1/40)-1 -> -0.0087180046 | J17: =(TableDE15a!C89/TableDE15a!C49)^(1/40)-1 -> 0.018367226 | K17: =(TableDE15a!B89/TableDE15a!B49)^(1/40)-1 -> 0.017843823
A20: 1950-2010 | B20: =(TableDE1!D150/TableDE1!D90)^(1/60)-1 -> 0.034544395 | C20: =(TableDE1!E150/TableDE1!E90)^(1/60)-1 -> 0.048803169 | D20: =(1+B20)/(1+G20)-1 -> 0.026350121 | E20: =(1+D20)*(1+J20)/(1+K20)-1 -> 0.028392442 | F20: =(1+D20)*(1+G20)/(1+I20)-1 -> 0.023036053 | G20: =(TableDE1!R150/TableDE1!R90)^(1/60)-1 -> 0.0079838975 | H20: =(TableDE1!S150/TableDE1!S90)^(1/60)-1 -> 0.01067398 | I20: =(TableDE1!T150/TableDE1!T90)^(1/60)-1 -> 0.011249205 | J20: =(TableDE15a!C149/TableDE15a!C89)^(1/60)-1 -> 0.028855168 | K20: =(TableDE15a!B149/TableDE15a!B89)^(1/60)-1 -> 0.026811928 | L20: =(TableDE15a!D149/TableDE15a!D89)^(1/60)-1 -> 0.025784365
A23: 1950-1980 | B23: =(TableDE1!D120/TableDE1!D90)^(1/30)-1 -> 0.049389004 | C23: =(TableDE1!E120/TableDE1!E90)^(1/30)-1 -> 0.061145219 | D23: =(1+B23)/(1+G23)-1 -> 0.042660853 | E23: =(1+D23)*(1+J23)/(1+K23)-1 -> 0.05033955 | F23: =(1+D23)*(1+G23)/(1+I23)-1 -> 0.03964557 | G23: =(TableDE1!R120/TableDE1!R90)^(1/30)-1 -> 0.0064528662 | H23: =(TableDE1!S120/TableDE1!S90)^(1/30)-1 -> 0.0083776424 | I23: =(TableDE1!T120/TableDE1!T90)^(1/30)-1 -> 0.0093718805 | J23: =(TableDE15a!C119/TableDE15a!C89)^(1/30)-1 -> 0.039337231 | K23: =(TableDE15a!B119/TableDE15a!B89)^(1/30)-1 -> 0.031738968 | L23: =(TableDE15a!D119/TableDE15a!D89)^(1/30)-1 -> 0.032030226
A26: 1980-2010 | B26: =(TableDE1!D150/TableDE1!D120)^(1/30)-1 -> 0.019909778 | C26: =(TableDE1!E150/TableDE1!E120)^(1/30)-1 -> 0.036604668 | D26: =(1+B26)/(1+G26)-1 -> 0.010294544 | E26: =(1+D26)*(1+J26)/(1+K26)-1 -> 0.0069039252 | F26: =(1+D26)*(1+G26)/(1+I26)-1 -> 0.0066918918 | G26: =(TableDE1!R150/TableDE1!R120)^(1/30)-1 -> 0.0095172577 | H26: =(TableDE1!S150/TableDE1!S120)^(1/30)-1 -> 0.012975546 | I26: =(TableDE1!T150/TableDE1!T120)^(1/30)-1 -> 0.013130021 | J26: =(TableDE15a!C149/TableDE15a!C119)^(1/30)-1 -> 0.01847882 | K26: =(TableDE15a!B149/TableDE15a!B119)^(1/30)-1 -> 0.021908416 | L26: =(TableDE15a!D149/TableDE15a!D119)^(1/30)-1 -> 0.019576305
A29: 1950-1970 | B29: =(TableDE1!D110/TableDE1!D90)^(1/20)-1 -> 0.061011767 | C29: =(TableDE1!E110/TableDE1!E90)^(1/20)-1 -> 0.072596948 | D29: =(1+B29)/(1+G29)-1 -> 0.05121042 | E29: =(1+D29)*(1+J29)/(1+K29)-1 -> 0.062702641 | F29: =(1+D29)*(1+G29)/(1+I29)-1 -> 0.047880286 | G29: =(TableDE1!R110/TableDE1!R90)^(1/20)-1 -> 0.0093238681 | H29: =(TableDE1!S110/TableDE1!S90)^(1/20)-1 -> 0.0099016213 | I29: =(TableDE1!T110/TableDE1!T90)^(1/20)-1 -> 0.01253147 | J29: =(TableDE15a!C109/TableDE15a!C89)^(1/20)-1 -> 0.033573108 | K29: =(TableDE15a!B109/TableDE15a!B89)^(1/20)-1 -> 0.022395898 | L29: =(TableDE15a!D109/TableDE15a!D89)^(1/20)-1 -> 0.023001325
A32: 1970-2010 | B32: =(TableDE1!D150/TableDE1!D110)^(1/40)-1 -> 0.021559338 | C32: =(TableDE1!E150/TableDE1!E110)^(1/40)-1 -> 0.037104952 | D32: =(1+B32)/(1+G32)-1 -> 0.014141321 | E32: =(1+D32)*(1+J32)/(1+K32)-1 -> 0.011655005 | F32: =(1+D32)*(1+G32)/(1+I32)-1 -> 0.010835704 | G32: =(TableDE1!R150/TableDE1!R110)^(1/40)-1 -> 0.0073145794 | H32: =(TableDE1!S150/TableDE1!S110)^(1/40)-1 -> 0.01106038 | I32: =(TableDE1!T150/TableDE1!T110)^(1/40)-1 -> 0.010608681 | J32: =(TableDE15a!C149/TableDE15a!C109)^(1/40)-1 -> 0.02650428 | K32: =(TableDE15a!B149/TableDE15a!B109)^(1/40)-1 -> 0.02902709 | L32: =(TableDE15a!D149/TableDE15a!D109)^(1/40)-1 -> 0.027178723
A35: 1970-1990 | B35: =(TableDE1!D130/TableDE1!D110)^(1/20)-1 -> 0.024898549 | C35: =(TableDE1!E130/TableDE1!E110)^(1/20)-1 -> 0.038573882 | D35: =(1+B35)/(1+G35)-1 -> 0.023164645 | E35: =(1+D35)*(1+J35)/(1+K35)-1 -> 0.024255107 | F35: =(1+D35)*(1+G35)/(1+I35)-1 -> 0.018042412 | G35: =(TableDE1!R130/TableDE1!R110)^(1/20)-1 -> 0.0016946474 | H35: =(TableDE1!S130/TableDE1!S110)^(1/20)-1 -> 0.0076828005 | I35: =(TableDE1!T130/TableDE1!T110)^(1/20)-1 -> 0.0067346273 | J35: =(TableDE15a!C129/TableDE15a!C109)^(1/20)-1 -> 0.039355757 | K35: =(TableDE15a!B129/TableDE15a!B109)^(1/20)-1 -> 0.038249219 | L35: =(TableDE15a!D129/TableDE15a!D109)^(1/20)-1 -> 0.037798927
A38: 1990-2010 | B38: =(TableDE1!D150/TableDE1!D130)^(1/20)-1 -> 0.018231007 | C38: =(TableDE1!E150/TableDE1!E130)^(1/20)-1 -> 0.0356381 | D38: =(1+B38)/(1+G38)-1 -> 0.0051975734 | E38: =(1+D38)*(1+J38)/(1+K38)-1 -> -0.00079009304 | F38: =(1+D38)*(1+G38)/(1+I38)-1 -> 0.0036800123 | G38: =(TableDE1!R150/TableDE1!R130)^(1/20)-1 -> 0.012966042 | H38: =(TableDE1!S150/TableDE1!S130)^(1/20)-1 -> 0.014449281 | I38: =(TableDE1!T150/TableDE1!T130)^(1/20)-1 -> 0.014497643 | J38: =(TableDE15a!C149/TableDE15a!C129)^(1/20)-1 -> 0.01381171 | K38: =(TableDE15a!B149/TableDE15a!B129)^(1/20)-1 -> 0.019886876 | L38: =(TableDE15a!D149/TableDE15a!D129)^(1/20)-1 -> 0.016667199
A41: 1950-1960 | B41: =(TableDE1!D100/TableDE1!D90)^(1/10)-1 -> 0.080816059 | C41: =(TableDE1!E100/TableDE1!E90)^(1/10)-1 -> 0.075442167 | D41: =(1+B41)/(1+G41)-1 -> 0.070976203 | E41: =(1+D41)*(1+J41)/(1+K41)-1 -> 0.082234285 | F41: =(1+D41)*(1+G41)/(1+I41)-1 -> 0.05637746 | G41: =(TableDE1!R100/TableDE1!R90)^(1/10)-1 -> 0.0091877442 | H41: =(TableDE1!S100/TableDE1!S90)^(1/10)-1 -> 0.012196403 | I41: =(TableDE1!T100/TableDE1!T90)^(1/10)-1 -> 0.023134343 | J41: =(TableDE15a!C99/TableDE15a!C89)^(1/10)-1 -> 0.029493921 | K41: =(TableDE15a!B99/TableDE15a!B89)^(1/10)-1 -> 0.018784478 | L41: =(TableDE15a!D99/TableDE15a!D89)^(1/10)-1 -> 0.019120155
A51: 1960-1970 | B51: =(TableDE1!D110/TableDE1!D100)^(1/10)-1 -> 0.041570358 | C51: =(TableDE1!E110/TableDE1!E100)^(1/10)-1 -> 0.069759256 | D51: =(1+B51)/(1+G51)-1 -> 0.03180943 | E51: =(1+D51)*(1+J51)/(1+K51)-1 -> 0.043523495 | F51: =(1+D51)*(1+G51)/(1+I51)-1 -> 0.039451461 | G51: =(TableDE1!R110/TableDE1!R100)^(1/10)-1 -> 0.0094600103 | H51: =(TableDE1!S110/TableDE1!S100)^(1/10)-1 -> 0.0076120425 | I51: =(TableDE1!T110/TableDE1!T100)^(1/10)-1 -> 0.0020384768 | J51: =(TableDE15a!C109/TableDE15a!C99)^(1/10)-1 -> 0.037668458 | K51: =(TableDE15a!B109/TableDE15a!B99)^(1/10)-1 -> 0.026020119 | L51: =(TableDE15a!D109/TableDE15a!D99)^(1/10)-1 -> 0.026897277
A61: 1970-1980 | B61: =(TableDE1!D120/TableDE1!D110)^(1/10)-1 -> 0.026524044 | C61: =(TableDE1!E120/TableDE1!E110)^(1/10)-1 -> 0.038607253 | D61: =(1+B61)/(1+G61)-1 -> 0.025769756 | E61: =(1+D61)*(1+J61)/(1+K61)-1 -> 0.026043177 | F61: =(1+D61)*(1+G61)/(1+I61)-1 -> 0.023369765 | G61: =(TableDE1!R120/TableDE1!R110)^(1/10)-1 -> 0.00073533882 | H61: =(TableDE1!S120/TableDE1!S110)^(1/10)-1 -> 0.0053365804 | I61: =(TableDE1!T120/TableDE1!T110)^(1/10)-1 -> 0.0030822482 | J61: =(TableDE15a!C119/TableDE15a!C109)^(1/10)-1 -> 0.050962095 | K61: =(TableDE15a!B119/TableDE15a!B109)^(1/10)-1 -> 0.050682033 | L61: =(TableDE15a!D119/TableDE15a!D109)^(1/10)-1 -> 0.050327793
A71: 1980-1990 | B71: =(TableDE1!D130/TableDE1!D120)^(1/10)-1 -> 0.023275627 | C71: =(TableDE1!E130/TableDE1!E120)^(1/10)-1 -> 0.038540512 | D71: =(1+B71)/(1+G71)-1 -> 0.020566151 | E71: =(1+D71)*(1+J71)/(1+K71)-1 -> 0.022470152 | F71: =(1+D71)*(1+G71)/(1+I71)-1 -> 0.012742793 | G71: =(TableDE1!R130/TableDE1!R120)^(1/10)-1 -> 0.0026548755 | H71: =(TableDE1!S130/TableDE1!S120)^(1/10)-1 -> 0.010034496 | I71: =(TableDE1!T130/TableDE1!T120)^(1/10)-1 -> 0.010400305 | J71: =(TableDE15a!C129/TableDE15a!C119)^(1/10)-1 -> 0.027877595 | K71: =(TableDE15a!B129/TableDE15a!B119)^(1/10)-1 -> 0.025963525 | L71: =(TableDE15a!D129/TableDE15a!D119)^(1/10)-1 -> 0.025419512
A81: 1990-2000 | B81: =(TableDE1!D140/TableDE1!D130)^(1/10)-1 -> 0.024329897 | C81: =(TableDE1!E140/TableDE1!E130)^(1/10)-1 -> 0.044493816 | D81: =(1+B81)/(1+G81)-1 -> -0.0022541998 | E81: =(1+D81)*(1+J81)/(1+K81)-1 -> -0.0084812357 | F81: =(1+D81)*(1+G81)/(1+I81)-1 -> -0.0018167326 | G81: =(TableDE1!R140/TableDE1!R130)^(1/10)-1 -> 0.026644158 | H81: =(TableDE1!S140/TableDE1!S130)^(1/10)-1 -> 0.026254613 | I81: =(TableDE1!T140/TableDE1!T130)^(1/10)-1 -> 0.026194217 | J81: =(TableDE15a!C139/TableDE15a!C129)^(1/10)-1 -> 0.017818365 | K81: =(TableDE15a!B139/TableDE15a!B129)^(1/10)-1 -> 0.024210571 | L81: =(TableDE15a!D139/TableDE15a!D129)^(1/10)-1 -> 0.019731847
A91: 2000-2010 | B91: =(TableDE1!D150/TableDE1!D140)^(1/10)-1 -> 0.01216843 | C91: =(TableDE1!E150/TableDE1!E140)^(1/10)-1 -> 0.026857466 | D91: =(1+B91)/(1+G91)-1 -> 0.012705001 | E91: =(1+D91)*(1+J91)/(1+K91)-1 -> 0.0069607092 | F91: =(1+D91)*(1+G91)/(1+I91)-1 -> 0.0092070263 | G91: =(TableDE1!R150/TableDE1!R140)^(1/10)-1 -> -0.00052983899 | H91: =(TableDE1!S150/TableDE1!S140)^(1/10)-1 -> 0.0027797503 | I91: =(TableDE1!T150/TableDE1!T140)^(1/10)-1 -> 0.0029343871 | J91: =(TableDE15a!C149/TableDE15a!C139)^(1/10)-1 -> 0.009820826 | K91: =(TableDE15a!B149/TableDE15a!B139)^(1/10)-1 -> 0.015581434 | L91: =(TableDE15a!D149/TableDE15a!D139)^(1/10)-1 -> 0.013611762

Sheet TableDE3b
